Workbook

Sheet Календарь
A1: Платёжный календарь
A2: Демо-компания (условные данные)
B3: 46314 | C3: 46321 | D3: 46328 | E3: 46335 | F3: 46342 | G3: 46349 | H3: 46356 | I3: 46363 | J3: 46370 | K3: 46377 | L3: 46384 | M3: 46391 | N3: 46398
A4: Неделя | B4: Неделя 1 19.10 — 25.10 | C4: Неделя 2 26.10 — 01.11 | D4: Неделя 3 02.11 — 08.11 | E4: Неделя 4 09.11 — 15.11 | F4: Неделя 5 16.11 — 22.11 | G4: Неделя 6 23.11 — 29.11 | H4: Неделя 7 30.11 — 06.12 | I4: Неделя 8 07.12 — 13.12 | J4: Неделя 9 14.12 — 20.12 | K4: Неделя 10 21.12 — 27.12 | L4: Неделя 11 28.12 — 03.01 | M4: Неделя 12 04.01 — 10.01 | N4: Неделя 13 11.01 — 17.01 | O4: Итого
A5: ПОСТУПЛЕНИЯ
A6: Поступления от заказчиков | B6: =SUMIFS('Сводный реестр'!$F$2:$F$46,'Сводный реестр'!$A$2:$A$46,"Поступление",'Сводный реестр'!$G$2:$G$46,">="&DATE(2026,10,19),'Сводный реестр'!$G$2:$G$46,"<="&DATE(2026,10,25),'Сводный реестр'!$E$2:$E$46,"Поступления от заказчиков") | C6: =SUMIFS('Сводный реестр'!$F$2:$F$46,'Сводный реестр'!$A$2:$A$46,"Поступление",'Сводный реестр'!$G$2:$G$46,">="&DATE(2026,10,26),'Сводный реестр'!$G$2:$G$46,"<="&DATE(2026,11,1),'Сводный реестр'!$E$2:$E$46,"Поступления от заказчиков") | D6: =SUMIFS('Сводный реестр'!$F$2:$F$46,'Сводный реестр'!$A$2:$A$46,"Поступление",'Сводный реестр'!$G$2:$G$46,">="&DATE(2026,11,2),'Сводный реестр'!$G$2:$G$46,"<="&DATE(2026,11,8),'Сводный реестр'!$E$2:$E$46,"Поступления от заказчиков") | E6: =SUMIFS('Сводный реестр'!$F$2:$F$46,'Сводный реестр'!$A$2:$A$46,"Поступление",'Сводный реестр'!$G$2:$G$46,">="&DATE(2026,11,9),'Сводный реестр'!$G$2:$G$46,"<="&DATE(2026,11,15),'Сводный реестр'!$E$2:$E$46,"Поступления от заказчиков") | F6: =SUMIFS('Сводный реестр'!$F$2:$F$46,'Сводный реестр'!$A$2:$A$46,"Поступление",'Сводный реестр'!$G$2:$G$46,">="&DATE(2026,11,16),'Сводный реестр'!$G$2:$G$46,"<="&DATE(2026,11,22),'Сводный реестр'!$E$2:$E$46,"Поступления от заказчиков") | G6: =SUMIFS('Сводный реестр'!$F$2:$F$46,'Сводный реестр'!$A$2:$A$46,"Поступление",'Сводный реестр'!$G$2:$G$46,">="&DATE(2026,11,23),'Сводный реестр'!$G$2:$G$46,"<="&DATE(2026,11,29),'Сводный реестр'!$E$2:$E$46,"Поступления от заказчиков") | H6: =SUMIFS('Сводный реестр'!$F$2:$F$46,'Сводный реестр'!$A$2:$A$46,"Поступление",'Сводный реестр'!$G$2:$G$46,">="&DATE(2026,11,30),'Сводный реестр'!$G$2:$G$46,"<="&DATE(2026,12,6),'Сводный реестр'!$E$2:$E$46,"Поступления от заказчиков") | I6: =SUMIFS('Сводный реестр'!$F$2:$F$46,'Сводный реестр'!$A$2:$A$46,"Поступление",'Сводный реестр'!$G$2:$G$46,">="&DATE(2026,12,7),'Сводный реестр'!$G$2:$G$46,"<="&DATE(2026,12,13),'Сводный реестр'!$E$2:$E$46,"Поступления от заказчиков") | J6: =SUMIFS('Сводный реестр'!$F$2:$F$46,'Сводный реестр'!$A$2:$A$46,"Поступление",'Сводный реестр'!$G$2:$G$46,">="&DATE(2026,12,14),'Сводный реестр'!$G$2:$G$46,"<="&DATE(2026,12,20),'Сводный реестр'!$E$2:$E$46,"Поступления от заказчиков") | K6: =SUMIFS('Сводный реестр'!$F$2:$F$46,'Сводный реестр'!$A$2:$A$46,"Поступление",'Сводный реестр'!$G$2:$G$46,">="&DATE(2026,12,21),'Сводный реестр'!$G$2:$G$46,"<="&DATE(2026,12,27),'Сводный реестр'!$E$2:$E$46,"Поступления от заказчиков") | L6: =SUMIFS('Сводный реестр'!$F$2:$F$46,'Сводный реестр'!$A$2:$A$46,"Поступление",'Сводный реестр'!$G$2:$G$46,">="&DATE(2026,12,28),'Сводный реестр'!$G$2:$G$46,"<="&DATE(2027,1,3),'Сводный реестр'!$E$2:$E$46,"Поступления от заказчиков") | M6: =SUMIFS('Сводный реестр'!$F$2:$F$46,'Сводный реестр'!$A$2:$A$46,"Поступление",'Сводный реестр'!$G$2:$G$46,">="&DATE(2027,1,4),'Сводный реестр'!$G$2:$G$46,"<="&DATE(2027,1,10),'Сводный реестр'!$E$2:$E$46,"Поступления от заказчиков") | N6: =SUMIFS('Сводный реестр'!$F$2:$F$46,'Сводный реестр'!$A$2:$A$46,"Поступление",'Сводный реестр'!$G$2:$G$46,">="&DATE(2027,1,11),'Сводный реестр'!$G$2:$G$46,"<="&DATE(2027,1,17),'Сводный реестр'!$E$2:$E$46,"Поступления от заказчиков") | O6: =SUM(B6:N6)
A7: Итого поступления | B7: =B6 | C7: =C6 | D7: =D6 | E7: =E6 | F7: =F6 | G7: =G6 | H7: =H6 | I7: =I6 | ... O7: =O6
A9: ПЛАТЕЖИ
A10: Налоги (приоритет 1) | B10: =SUMIFS('Сводный реестр'!$F$2:$F$46,'Сводный реестр'!$A$2:$A$46,"Платёж",'Сводный реестр'!$G$2:$G$46,">="&DATE(2026,10,19),'Сводный реестр'!$G$2:$G$46,"<="&DATE(2026,10,25),'Сводный реестр'!$E$2:$E$46,"Налоги") | C10: =SUMIFS('Сводный реестр'!$F$2:$F$46,'Сводный реестр'!$A$2:$A$46,"Платёж",'Сводный реестр'!$G$2:$G$46,">="&DATE(2026,10,26),'Сводный реестр'!$G$2:$G$46,"<="&DATE(2026,11,1),'Сводный реестр'!$E$2:$E$46,"Налоги") | D10: =SUMIFS('Сводный реестр'!$F$2:$F$46,'Сводный реестр'!$A$2:$A$46,"Платёж",'Сводный реестр'!$G$2:$G$46,">="&DATE(2026,11,2),'Сводный реестр'!$G$2:$G$46,"<="&DATE(2026,11,8),'Сводный реестр'!$E$2:$E$46,"Налоги") | E10: =SUMIFS('Сводный реестр'!$F$2:$F$46,'Сводный реестр'!$A$2:$A$46,"Платёж",'Сводный реестр'!$G$2:$G$46,">="&DATE(2026,11,9),'Сводный реестр'!$G$2:$G$46,"<="&DATE(2026,11,15),'Сводный реестр'!$E$2:$E$46,"Налоги") | F10: =SUMIFS('Сводный реестр'!$F$2:$F$46,'Сводный реестр'!$A$2:$A$46,"Платёж",'Сводный реестр'!$G$2:$G$46,">="&DATE(2026,11,16),'Сводный реестр'!$G$2:$G$46,"<="&DATE(2026,11,22),'Сводный реестр'!$E$2:$E$46,"Налоги") | G10: =SUMIFS('Сводный реестр'!$F$2:$F$46,'Сводный реестр'!$A$2:$A$46,"Платёж",'Сводный реестр'!$G$2:$G$46,">="&DATE(2026,11,23),'Сводный реестр'!$G$2:$G$46,"<="&DATE(2026,11,29),'Сводный реестр'!$E$2:$E$46,"Налоги") | H10: =SUMIFS('Сводный реестр'!$F$2:$F$46,'Сводный реестр'!$A$2:$A$46,"Платёж",'Сводный реестр'!$G$2:$G$46,">="&DATE(2026,11,30),'Сводный реестр'!$G$2:$G$46,"<="&DATE(2026,12,6),'Сводный реестр'!$E$2:$E$46,"Налоги") | I10: =SUMIFS('Сводный реестр'!$F$2:$F$46,'Сводный реестр'!$A$2:$A$46,"Платёж",'Сводный реестр'!$G$2:$G$46,">="&DATE(2026,12,7),'Сводный реестр'!$G$2:$G$46,"<="&DATE(2026,12,13),'Сводный реестр'!$E$2:$E$46,"Налоги") | J10: =SUMIFS('Сводный реестр'!$F$2:$F$46,'Сводный реестр'!$A$2:$A$46,"Платёж",'Сводный реестр'!$G$2:$G$46,">="&DATE(2026,12,14),'Сводный реестр'!$G$2:$G$46,"<="&DATE(2026,12,20),'Сводный реестр'!$E$2:$E$46,"Налоги") | K10: =SUMIFS('Сводный реестр'!$F$2:$F$46,'Сводный реестр'!$A$2:$A$46,"Платёж",'Сводный реестр'!$G$2:$G$46,">="&DATE(2026,12,21),'Сводный реестр'!$G$2:$G$46,"<="&DATE(2026,12,27),'Сводный реестр'!$E$2:$E$46,"Налоги") | L10: =SUMIFS('Сводный реестр'!$F$2:$F$46,'Сводный реестр'!$A$2:$A$46,"Платёж",'Сводный реестр'!$G$2:$G$46,">="&DATE(2026,12,28),'Сводный реестр'!$G$2:$G$46,"<="&DATE(2027,1,3),'Сводный реестр'!$E$2:$E$46,"Налоги") | M10: =SUMIFS('Сводный реестр'!$F$2:$F$46,'Сводный реестр'!$A$2:$A$46,"Платёж",'Сводный реестр'!$G$2:$G$46,">="&DATE(2027,1,4),'Сводный реестр'!$G$2:$G$46,"<="&DATE(2027,1,10),'Сводный реестр'!$E$2:$E$46,"Налоги") | N10: =SUMIFS('Сводный реестр'!$F$2:$F$46,'Сводный реестр'!$A$2:$A$46,"Платёж",'Сводный реестр'!$G$2:$G$46,">="&DATE(2027,1,11),'Сводный реестр'!$G$2:$G$46,"<="&DATE(2027,1,17),'Сводный реестр'!$E$2:$E$46,"Налоги") | O10: =SUM(B10:N10)
A11: Погашение кредита (приоритет 1) | B11: =SUMIFS('Сводный реестр'!$F$2:$F$46,'Сводный реестр'!$A$2:$A$46,"Платёж",'Сводный реестр'!$G$2:$G$46,">="&DATE(2026,10,19),'Сводный реестр'!$G$2:$G$46,"<="&DATE(2026,10,25),'Сводный реестр'!$E$2:$E$46,"Погашение кредита") | C11: =SUMIFS('Сводный реестр'!$F$2:$F$46,'Сводный реестр'!$A$2:$A$46,"Платёж",'Сводный реестр'!$G$2:$G$46,">="&DATE(2026,10,26),'Сводный реестр'!$G$2:$G$46,"<="&DATE(2026,11,1),'Сводный реестр'!$E$2:$E$46,"Погашение кредита") | D11: =SUMIFS('Сводный реестр'!$F$2:$F$46,'Сводный реестр'!$A$2:$A$46,"Платёж",'Сводный реестр'!$G$2:$G$46,">="&DATE(2026,11,2),'Сводный реестр'!$G$2:$G$46,"<="&DATE(2026,11,8),'Сводный реестр'!$E$2:$E$46,"Погашение кредита") | E11: =SUMIFS('Сводный реестр'!$F$2:$F$46,'Сводный реестр'!$A$2:$A$46,"Платёж",'Сводный реестр'!$G$2:$G$46,">="&DATE(2026,11,9),'Сводный реестр'!$G$2:$G$46,"<="&DATE(2026,11,15),'Сводный реестр'!$E$2:$E$46,"Погашение кредита") | F11: =SUMIFS('Сводный реестр'!$F$2:$F$46,'Сводный реестр'!$A$2:$A$46,"Платёж",'Сводный реестр'!$G$2:$G$46,">="&DATE(2026,11,16),'Сводный реестр'!$G$2:$G$46,"<="&DATE(2026,11,22),'Сводный реестр'!$E$2:$E$46,"Погашение кредита") | G11: =SUMIFS('Сводный реестр'!$F$2:$F$46,'Сводный реестр'!$A$2:$A$46,"Платёж",'Сводный реестр'!$G$2:$G$46,">="&DATE(2026,11,23),'Сводный реестр'!$G$2:$G$46,"<="&DATE(2026,11,29),'Сводный реестр'!$E$2:$E$46,"Погашение кредита") | H11: =SUMIFS('Сводный реестр'!$F$2:$F$46,'Сводный реестр'!$A$2:$A$46,"Платёж",'Сводный реестр'!$G$2:$G$46,">="&DATE(2026,11,30),'Сводный реестр'!$G$2:$G$46,"<="&DATE(2026,12,6),'Сводный реестр'!$E$2:$E$46,"Погашение кредита") | I11: =SUMIFS('Сводный реестр'!$F$2:$F$46,'Сводный реестр'!$A$2:$A$46,"Платёж",'Сводный реестр'!$G$2:$G$46,">="&DATE(2026,12,7),'Сводный реестр'!$G$2:$G$46,"<="&DATE(2026,12,13),'Сводный реестр'!$E$2:$E$46,"Погашение кредита") | J11: =SUMIFS('Сводный реестр'!$F$2:$F$46,'Сводный реестр'!$A$2:$A$46,"Платёж",'Сводный реестр'!$G$2:$G$46,">="&DATE(2026,12,14),'Сводный реестр'!$G$2:$G$46,"<="&DATE(2026,12,20),'Сводный реестр'!$E$2:$E$46,"Погашение кредита") | K11: =SUMIFS('Сводный реестр'!$F$2:$F$46,'Сводный реестр'!$A$2:$A$46,"Платёж",'Сводный реестр'!$G$2:$G$46,">="&DATE(2026,12,21),'Сводный реестр'!$G$2:$G$46,"<="&DATE(2026,12,27),'Сводный реестр'!$E$2:$E$46,"Погашение кредита") | L11: =SUMIFS('Сводный реестр'!$F$2:$F$46,'Сводный реестр'!$A$2:$A$46,"Платёж",'Сводный реестр'!$G$2:$G$46,">="&DATE(2026,12,28),'Сводный реестр'!$G$2:$G$46,"<="&DATE(2027,1,3),'Сводный реестр'!$E$2:$E$46,"Погашение кредита") | M11: =SUMIFS('Сводный реестр'!$F$2:$F$46,'Сводный реестр'!$A$2:$A$46,"Платёж",'Сводный реестр'!$G$2:$G$46,">="&DATE(2027,1,4),'Сводный реестр'!$G$2:$G$46,"<="&DATE(2027,1,10),'Сводный реестр'!$E$2:$E$46,"Погашение кредита") | N11: =SUMIFS('Сводный реестр'!$F$2:$F$46,'Сводный реестр'!$A$2:$A$46,"Платёж",'Сводный реестр'!$G$2:$G$46,">="&DATE(2027,1,11),'Сводный реестр'!$G$2:$G$46,"<="&DATE(2027,1,17),'Сводный реестр'!$E$2:$E$46,"Погашение кредита") | O11: =SUM(B11:N11)
A12: Проценты по кредитам (приоритет 1) | B12: =SUMIFS('Сводный реестр'!$F$2:$F$46,'Сводный реестр'!$A$2:$A$46,"Платёж",'Сводный реестр'!$G$2:$G$46,">="&DATE(2026,10,19),'Сводный реестр'!$G$2:$G$46,"<="&DATE(2026,10,25),'Сводный реестр'!$E$2:$E$46,"Проценты по кредитам") | C12: =SUMIFS('Сводный реестр'!$F$2:$F$46,'Сводный реестр'!$A$2:$A$46,"Платёж",'Сводный реестр'!$G$2:$G$46,">="&DATE(2026,10,26),'Сводный реестр'!$G$2:$G$46,"<="&DATE(2026,11,1),'Сводный реестр'!$E$2:$E$46,"Проценты по кредитам") | D12: =SUMIFS('Сводный реестр'!$F$2:$F$46,'Сводный реестр'!$A$2:$A$46,"Платёж",'Сводный реестр'!$G$2:$G$46,">="&DATE(2026,11,2),'Сводный реестр'!$G$2:$G$46,"<="&DATE(2026,11,8),'Сводный реестр'!$E$2:$E$46,"Проценты по кредитам") | E12: =SUMIFS('Сводный реестр'!$F$2:$F$46,'Сводный реестр'!$A$2:$A$46,"Платёж",'Сводный реестр'!$G$2:$G$46,">="&DATE(2026,11,9),'Сводный реестр'!$G$2:$G$46,"<="&DATE(2026,11,15),'Сводный реестр'!$E$2:$E$46,"Проценты по кредитам") | F12: =SUMIFS('Сводный реестр'!$F$2:$F$46,'Сводный реестр'!$A$2:$A$46,"Платёж",'Сводный реестр'!$G$2:$G$46,">="&DATE(2026,11,16),'Сводный реестр'!$G$2:$G$46,"<="&DATE(2026,11,22),'Сводный реестр'!$E$2:$E$46,"Проценты по кредитам") | G12: =SUMIFS('Сводный реестр'!$F$2:$F$46,'Сводный реестр'!$A$2:$A$46,"Платёж",'Сводный реестр'!$G$2:$G$46,">="&DATE(2026,11,23),'Сводный реестр'!$G$2:$G$46,"<="&DATE(2026,11,29),'Сводный реестр'!$E$2:$E$46,"Проценты по кредитам") | H12: =SUMIFS('Сводный реестр'!$F$2:$F$46,'Сводный реестр'!$A$2:$A$46,"Платёж",'Сводный реестр'!$G$2:$G$46,">="&DATE(2026,11,30),'Сводный реестр'!$G$2:$G$46,"<="&DATE(2026,12,6),'Сводный реестр'!$E$2:$E$46,"Проценты по кредитам") | I12: =SUMIFS('Сводный реестр'!$F$2:$F$46,'Сводный реестр'!$A$2:$A$46,"Платёж",'Сводный реестр'!$G$2:$G$46,">="&DATE(2026,12,7),'Сводный реестр'!$G$2:$G$46,"<="&DATE(2026,12,13),'Сводный реестр'!$E$2:$E$46,"Проценты по кредитам") | J12: =SUMIFS('Сводный реестр'!$F$2:$F$46,'Сводный реестр'!$A$2:$A$46,"Платёж",'Сводный реестр'!$G$2:$G$46,">="&DATE(2026,12,14),'Сводный реестр'!$G$2:$G$46,"<="&DATE(2026,12,20),'Сводный реестр'!$E$2:$E$46,"Проценты по кредитам") | K12: =SUMIFS('Сводный реестр'!$F$2:$F$46,'Сводный реестр'!$A$2:$A$46,"Платёж",'Сводный реестр'!$G$2:$G$46,">="&DATE(2026,12,21),'Сводный реестр'!$G$2:$G$46,"<="&DATE(2026,12,27),'Сводный реестр'!$E$2:$E$46,"Проценты по кредитам") | L12: =SUMIFS('Сводный реестр'!$F$2:$F$46,'Сводный реестр'!$A$2:$A$46,"Платёж",'Сводный реестр'!$G$2:$G$46,">="&DATE(2026,12,28),'Сводный реестр'!$G$2:$G$46,"<="&DATE(2027,1,3),'Сводный реестр'!$E$2:$E$46,"Проценты по кредитам") | M12: =SUMIFS('Сводный реестр'!$F$2:$F$46,'Сводный реестр'!$A$2:$A$46,"Платёж",'Сводный реестр'!$G$2:$G$46,">="&DATE(2027,1,4),'Сводный реестр'!$G$2:$G$46,"<="&DATE(2027,1,10),'Сводный реестр'!$E$2:$E$46,"Проценты по кредитам") | N12: =SUMIFS('Сводный реестр'!$F$2:$F$46,'Сводный реестр'!$A$2:$A$46,"Платёж",'Сводный реестр'!$G$2:$G$46,">="&DATE(2027,1,11),'Сводный реестр'!$G$2:$G$46,"<="&DATE(2027,1,17),'Сводный реестр'!$E$2:$E$46,"Проценты по кредитам") | O12: =SUM(B12:N12)
A13: Страховые взносы (приоритет 1) | B13: =SUMIFS('Сводный реестр'!$F$2:$F$46,'Сводный реестр'!$A$2:$A$46,"Платёж",'Сводный реестр'!$G$2:$G$46,">="&DATE(2026,10,19),'Сводный реестр'!$G$2:$G$46,"<="&DATE(2026,10,25),'Сводный реестр'!$E$2:$E$46,"Страховые взносы") | C13: =SUMIFS('Сводный реестр'!$F$2:$F$46,'Сводный реестр'!$A$2:$A$46,"Платёж",'Сводный реестр'!$G$2:$G$46,">="&DATE(2026,10,26),'Сводный реестр'!$G$2:$G$46,"<="&DATE(2026,11,1),'Сводный реестр'!$E$2:$E$46,"Страховые взносы") | D13: =SUMIFS('Сводный реестр'!$F$2:$F$46,'Сводный реестр'!$A$2:$A$46,"Платёж",'Сводный реестр'!$G$2:$G$46,">="&DATE(2026,11,2),'Сводный реестр'!$G$2:$G$46,"<="&DATE(2026,11,8),'Сводный реестр'!$E$2:$E$46,"Страховые взносы") | E13: =SUMIFS('Сводный реестр'!$F$2:$F$46,'Сводный реестр'!$A$2:$A$46,"Платёж",'Сводный реестр'!$G$2:$G$46,">="&DATE(2026,11,9),'Сводный реестр'!$G$2:$G$46,"<="&DATE(2026,11,15),'Сводный реестр'!$E$2:$E$46,"Страховые взносы") | F13: =SUMIFS('Сводный реестр'!$F$2:$F$46,'Сводный реестр'!$A$2:$A$46,"Платёж",'Сводный реестр'!$G$2:$G$46,">="&DATE(2026,11,16),'Сводный реестр'!$G$2:$G$46,"<="&DATE(2026,11,22),'Сводный реестр'!$E$2:$E$46,"Страховые взносы") | G13: =SUMIFS('Сводный реестр'!$F$2:$F$46,'Сводный реестр'!$A$2:$A$46,"Платёж",'Сводный реестр'!$G$2:$G$46,">="&DATE(2026,11,23),'Сводный реестр'!$G$2:$G$46,"<="&DATE(2026,11,29),'Сводный реестр'!$E$2:$E$46,"Страховые взносы") | H13: =SUMIFS('Сводный реестр'!$F$2:$F$46,'Сводный реестр'!$A$2:$A$46,"Платёж",'Сводный реестр'!$G$2:$G$46,">="&DATE(2026,11,30),'Сводный реестр'!$G$2:$G$46,"<="&DATE(2026,12,6),'Сводный реестр'!$E$2:$E$46,"Страховые взносы") | I13: =SUMIFS('Сводный реестр'!$F$2:$F$46,'Сводный реестр'!$A$2:$A$46,"Платёж",'Сводный реестр'!$G$2:$G$46,">="&DATE(2026,12,7),'Сводный реестр'!$G$2:$G$46,"<="&DATE(2026,12,13),'Сводный реестр'!$E$2:$E$46,"Страховые взносы") | J13: =SUMIFS('Сводный реестр'!$F$2:$F$46,'Сводный реестр'!$A$2:$A$46,"Платёж",'Сводный реестр'!$G$2:$G$46,">="&DATE(2026,12,14),'Сводный реестр'!$G$2:$G$46,"<="&DATE(2026,12,20),'Сводный реестр'!$E$2:$E$46,"Страховые взносы") | K13: =SUMIFS('Сводный реестр'!$F$2:$F$46,'Сводный реестр'!$A$2:$A$46,"Платёж",'Сводный реестр'!$G$2:$G$46,">="&DATE(2026,12,21),'Сводный реестр'!$G$2:$G$46,"<="&DATE(2026,12,27),'Сводный реестр'!$E$2:$E$46,"Страховые взносы") | L13: =SUMIFS('Сводный реестр'!$F$2:$F$46,'Сводный реестр'!$A$2:$A$46,"Платёж",'Сводный реестр'!$G$2:$G$46,">="&DATE(2026,12,28),'Сводный реестр'!$G$2:$G$46,"<="&DATE(2027,1,3),'Сводный реестр'!$E$2:$E$46,"Страховые взносы") | M13: =SUMIFS('Сводный реестр'!$F$2:$F$46,'Сводный реестр'!$A$2:$A$46,"Платёж",'Сводный реестр'!$G$2:$G$46,">="&DATE(2027,1,4),'Сводный реестр'!$G$2:$G$46,"<="&DATE(2027,1,10),'Сводный реестр'!$E$2:$E$46,"Страховые взносы") | N13: =SUMIFS('Сводный реестр'!$F$2:$F$46,'Сводный реестр'!$A$2:$A$46,"Платёж",'Сводный реестр'!$G$2:$G$46,">="&DATE(2027,1,11),'Сводный реестр'!$G$2:$G$46,"<="&DATE(2027,1,17),'Сводный реестр'!$E$2:$E$46,"Страховые взносы") | O13: =SUM(B13:N13)
A14: ФОТ (приоритет 1) | B14: =SUMIFS('Сводный реестр'!$F$2:$F$46,'Сводный реестр'!$A$2:$A$46,"Платёж",'Сводный реестр'!$G$2:$G$46,">="&DATE(2026,10,19),'Сводный реестр'!$G$2:$G$46,"<="&DATE(2026,10,25),'Сводный реестр'!$E$2:$E$46,"ФОТ") | C14: =SUMIFS('Сводный реестр'!$F$2:$F$46,'Сводный реестр'!$A$2:$A$46,"Платёж",'Сводный реестр'!$G$2:$G$46,">="&DATE(2026,10,26),'Сводный реестр'!$G$2:$G$46,"<="&DATE(2026,11,1),'Сводный реестр'!$E$2:$E$46,"ФОТ") | D14: =SUMIFS('Сводный реестр'!$F$2:$F$46,'Сводный реестр'!$A$2:$A$46,"Платёж",'Сводный реестр'!$G$2:$G$46,">="&DATE(2026,11,2),'Сводный реестр'!$G$2:$G$46,"<="&DATE(2026,11,8),'Сводный реестр'!$E$2:$E$46,"ФОТ") | E14: =SUMIFS('Сводный реестр'!$F$2:$F$46,'Сводный реестр'!$A$2:$A$46,"Платёж",'Сводный реестр'!$G$2:$G$46,">="&DATE(2026,11,9),'Сводный реестр'!$G$2:$G$46,"<="&DATE(2026,11,15),'Сводный реестр'!$E$2:$E$46,"ФОТ") | F14: =SUMIFS('Сводный реестр'!$F$2:$F$46,'Сводный реестр'!$A$2:$A$46,"Платёж",'Сводный реестр'!$G$2:$G$46,">="&DATE(2026,11,16),'Сводный реестр'!$G$2:$G$46,"<="&DATE(2026,11,22),'Сводный реестр'!$E$2:$E$46,"ФОТ") | G14: =SUMIFS('Сводный реестр'!$F$2:$F$46,'Сводный реестр'!$A$2:$A$46,"Платёж",'Сводный реестр'!$G$2:$G$46,">="&DATE(2026,11,23),'Сводный реестр'!$G$2:$G$46,"<="&DATE(2026,11,29),'Сводный реестр'!$E$2:$E$46,"ФОТ") | H14: =SUMIFS('Сводный реестр'!$F$2:$F$46,'Сводный реестр'!$A$2:$A$46,"Платёж",'Сводный реестр'!$G$2:$G$46,">="&DATE(2026,11,30),'Сводный реестр'!$G$2:$G$46,"<="&DATE(2026,12,6),'Сводный реестр'!$E$2:$E$46,"ФОТ") | I14: =SUMIFS('Сводный реестр'!$F$2:$F$46,'Сводный реестр'!$A$2:$A$46,"Платёж",'Сводный реестр'!$G$2:$G$46,">="&DATE(2026,12,7),'Сводный реестр'!$G$2:$G$46,"<="&DATE(2026,12,13),'Сводный реестр'!$E$2:$E$46,"ФОТ") | J14: =SUMIFS('Сводный реестр'!$F$2:$F$46,'Сводный реестр'!$A$2:$A$46,"Платёж",'Сводный реестр'!$G$2:$G$46,">="&DATE(2026,12,14),'Сводный реестр'!$G$2:$G$46,"<="&DATE(2026,12,20),'Сводный реестр'!$E$2:$E$46,"ФОТ") | K14: =SUMIFS('Сводный реестр'!$F$2:$F$46,'Сводный реестр'!$A$2:$A$46,"Платёж",'Сводный реестр'!$G$2:$G$46,">="&DATE(2026,12,21),'Сводный реестр'!$G$2:$G$46,"<="&DATE(2026,12,27),'Сводный реестр'!$E$2:$E$46,"ФОТ") | L14: =SUMIFS('Сводный реестр'!$F$2:$F$46,'Сводный реестр'!$A$2:$A$46,"Платёж",'Сводный реестр'!$G$2:$G$46,">="&DATE(2026,12,28),'Сводный реестр'!$G$2:$G$46,"<="&DATE(2027,1,3),'Сводный реестр'!$E$2:$E$46,"ФОТ") | M14: =SUMIFS('Сводный реестр'!$F$2:$F$46,'Сводный реестр'!$A$2:$A$46,"Платёж",'Сводный реестр'!$G$2:$G$46,">="&DATE(2027,1,4),'Сводный реестр'!$G$2:$G$46,"<="&DATE(2027,1,10),'Сводный реестр'!$E$2:$E$46,"ФОТ") | N14: =SUMIFS('Сводный реестр'!$F$2:$F$46,'Сводный реестр'!$A$2:$A$46,"Платёж",'Сводный реестр'!$G$2:$G$46,">="&DATE(2027,1,11),'Сводный реестр'!$G$2:$G$46,"<="&DATE(2027,1,17),'Сводный реестр'!$E$2:$E$46,"ФОТ") | O14: =SUM(B14:N14)
A15: Аренда (приоритет 2) | B15: =SUMIFS('Сводный реестр'!$F$2:$F$46,'Сводный реестр'!$A$2:$A$46,"Платёж",'Сводный реестр'!$G$2:$G$46,">="&DATE(2026,10,19),'Сводный реестр'!$G$2:$G$46,"<="&DATE(2026,10,25),'Сводный реестр'!$E$2:$E$46,"Аренда") | C15: =SUMIFS('Сводный реестр'!$F$2:$F$46,'Сводный реестр'!$A$2:$A$46,"Платёж",'Сводный реестр'!$G$2:$G$46,">="&DATE(2026,10,26),'Сводный реестр'!$G$2:$G$46,"<="&DATE(2026,11,1),'Сводный реестр'!$E$2:$E$46,"Аренда") | D15: =SUMIFS('Сводный реестр'!$F$2:$F$46,'Сводный реестр'!$A$2:$A$46,"Платёж",'Сводный реестр'!$G$2:$G$46,">="&DATE(2026,11,2),'Сводный реестр'!$G$2:$G$46,"<="&DATE(2026,11,8),'Сводный реестр'!$E$2:$E$46,"Аренда") | E15: =SUMIFS('Сводный реестр'!$F$2:$F$46,'Сводный реестр'!$A$2:$A$46,"Платёж",'Сводный реестр'!$G$2:$G$46,">="&DATE(2026,11,9),'Сводный реестр'!$G$2:$G$46,"<="&DATE(2026,11,15),'Сводный реестр'!$E$2:$E$46,"Аренда") | F15: =SUMIFS('Сводный реестр'!$F$2:$F$46,'Сводный реестр'!$A$2:$A$46,"Платёж",'Сводный реестр'!$G$2:$G$46,">="&DATE(2026,11,16),'Сводный реестр'!$G$2:$G$46,"<="&DATE(2026,11,22),'Сводный реестр'!$E$2:$E$46,"Аренда") | G15: =SUMIFS('Сводный реестр'!$F$2:$F$46,'Сводный реестр'!$A$2:$A$46,"Платёж",'Сводный реестр'!$G$2:$G$46,">="&DATE(2026,11,23),'Сводный реестр'!$G$2:$G$46,"<="&DATE(2026,11,29),'Сводный реестр'!$E$2:$E$46,"Аренда") | H15: =SUMIFS('Сводный реестр'!$F$2:$F$46,'Сводный реестр'!$A$2:$A$46,"Платёж",'Сводный реестр'!$G$2:$G$46,">="&DATE(2026,11,30),'Сводный реестр'!$G$2:$G$46,"<="&DATE(2026,12,6),'Сводный реестр'!$E$2:$E$46,"Аренда") | I15: =SUMIFS('Сводный реестр'!$F$2:$F$46,'Сводный реестр'!$A$2:$A$46,"Платёж",'Сводный реестр'!$G$2:$G$46,">="&DATE(2026,12,7),'Сводный реестр'!$G$2:$G$46,"<="&DATE(2026,12,13),'Сводный реестр'!$E$2:$E$46,"Аренда") | J15: =SUMIFS('Сводный реестр'!$F$2:$F$46,'Сводный реестр'!$A$2:$A$46,"Платёж",'Сводный реестр'!$G$2:$G$46,">="&DATE(2026,12,14),'Сводный реестр'!$G$2:$G$46,"<="&DATE(2026,12,20),'Сводный реестр'!$E$2:$E$46,"Аренда") | K15: =SUMIFS('Сводный реестр'!$F$2:$F$46,'Сводный реестр'!$A$2:$A$46,"Платёж",'Сводный реестр'!$G$2:$G$46,">="&DATE(2026,12,21),'Сводный реестр'!$G$2:$G$46,"<="&DATE(2026,12,27),'Сводный реестр'!$E$2:$E$46,"Аренда") | L15: =SUMIFS('Сводный реестр'!$F$2:$F$46,'Сводный реестр'!$A$2:$A$46,"Платёж",'Сводный реестр'!$G$2:$G$46,">="&DATE(2026,12,28),'Сводный реестр'!$G$2:$G$46,"<="&DATE(2027,1,3),'Сводный реестр'!$E$2:$E$46,"Аренда") | M15: =SUMIFS('Сводный реестр'!$F$2:$F$46,'Сводный реестр'!$A$2:$A$46,"Платёж",'Сводный реестр'!$G$2:$G$46,">="&DATE(2027,1,4),'Сводный реестр'!$G$2:$G$46,"<="&DATE(2027,1,10),'Сводный реестр'!$E$2:$E$46,"Аренда") | N15: =SUMIFS('Сводный реестр'!$F$2:$F$46,'Сводный реестр'!$A$2:$A$46,"Платёж",'Сводный реестр'!$G$2:$G$46,">="&DATE(2027,1,11),'Сводный реестр'!$G$2:$G$46,"<="&DATE(2027,1,17),'Сводный реестр'!$E$2:$E$46,"Аренда") | O15: =SUM(B15:N15)
A16: Лизинг (приоритет 2) | B16: =SUMIFS('Сводный реестр'!$F$2:$F$46,'Сводный реестр'!$A$2:$A$46,"Платёж",'Сводный реестр'!$G$2:$G$46,">="&DATE(2026,10,19),'Сводный реестр'!$G$2:$G$46,"<="&DATE(2026,10,25),'Сводный реестр'!$E$2:$E$46,"Лизинг") | C16: =SUMIFS('Сводный реестр'!$F$2:$F$46,'Сводный реестр'!$A$2:$A$46,"Платёж",'Сводный реестр'!$G$2:$G$46,">="&DATE(2026,10,26),'Сводный реестр'!$G$2:$G$46,"<="&DATE(2026,11,1),'Сводный реестр'!$E$2:$E$46,"Лизинг") | D16: =SUMIFS('Сводный реестр'!$F$2:$F$46,'Сводный реестр'!$A$2:$A$46,"Платёж",'Сводный реестр'!$G$2:$G$46,">="&DATE(2026,11,2),'Сводный реестр'!$G$2:$G$46,"<="&DATE(2026,11,8),'Сводный реестр'!$E$2:$E$46,"Лизинг") | E16: =SUMIFS('Сводный реестр'!$F$2:$F$46,'Сводный реестр'!$A$2:$A$46,"Платёж",'Сводный реестр'!$G$2:$G$46,">="&DATE(2026,11,9),'Сводный реестр'!$G$2:$G$46,"<="&DATE(2026,11,15),'Сводный реестр'!$E$2:$E$46,"Лизинг") | F16: =SUMIFS('Сводный реестр'!$F$2:$F$46,'Сводный реестр'!$A$2:$A$46,"Платёж",'Сводный реестр'!$G$2:$G$46,">="&DATE(2026,11,16),'Сводный реестр'!$G$2:$G$46,"<="&DATE(2026,11,22),'Сводный реестр'!$E$2:$E$46,"Лизинг") | G16: =SUMIFS('Сводный реестр'!$F$2:$F$46,'Сводный реестр'!$A$2:$A$46,"Платёж",'Сводный реестр'!$G$2:$G$46,">="&DATE(2026,11,23),'Сводный реестр'!$G$2:$G$46,"<="&DATE(2026,11,29),'Сводный реестр'!$E$2:$E$46,"Лизинг") | H16: =SUMIFS('Сводный реестр'!$F$2:$F$46,'Сводный реестр'!$A$2:$A$46,"Платёж",'Сводный реестр'!$G$2:$G$46,">="&DATE(2026,11,30),'Сводный реестр'!$G$2:$G$46,"<="&DATE(2026,12,6),'Сводный реестр'!$E$2:$E$46,"Лизинг") | I16: =SUMIFS('Сводный реестр'!$F$2:$F$46,'Сводный реестр'!$A$2:$A$46,"Платёж",'Сводный реестр'!$G$2:$G$46,">="&DATE(2026,12,7),'Сводный реестр'!$G$2:$G$46,"<="&DATE(2026,12,13),'Сводный реестр'!$E$2:$E$46,"Лизинг") | J16: =SUMIFS('Сводный реестр'!$F$2:$F$46,'Сводный реестр'!$A$2:$A$46,"Платёж",'Сводный реестр'!$G$2:$G$46,">="&DATE(2026,12,14),'Сводный реестр'!$G$2:$G$46,"<="&DATE(2026,12,20),'Сводный реестр'!$E$2:$E$46,"Лизинг") | K16: =SUMIFS('Сводный реестр'!$F$2:$F$46,'Сводный реестр'!$A$2:$A$46,"Платёж",'Сводный реестр'!$G$2:$G$46,">="&DATE(2026,12,21),'Сводный реестр'!$G$2:$G$46,"<="&DATE(2026,12,27),'Сводный реестр'!$E$2:$E$46,"Лизинг") | L16: =SUMIFS('Сводный реестр'!$F$2:$F$46,'Сводный реестр'!$A$2:$A$46,"Платёж",'Сводный реестр'!$G$2:$G$46,">="&DATE(2026,12,28),'Сводный реестр'!$G$2:$G$46,"<="&DATE(2027,1,3),'Сводный реестр'!$E$2:$E$46,"Лизинг") | M16: =SUMIFS('Сводный реестр'!$F$2:$F$46,'Сводный реестр'!$A$2:$A$46,"Платёж",'Сводный реестр'!$G$2:$G$46,">="&DATE(2027,1,4),'Сводный реестр'!$G$2:$G$46,"<="&DATE(2027,1,10),'Сводный реестр'!$E$2:$E$46,"Лизинг") | N16: =SUMIFS('Сводный реестр'!$F$2:$F$46,'Сводный реестр'!$A$2:$A$46,"Платёж",'Сводный реестр'!$G$2:$G$46,">="&DATE(2027,1,11),'Сводный реестр'!$G$2:$G$46,"<="&DATE(2027,1,17),'Сводный реестр'!$E$2:$E$46,"Лизинг") | O16: =SUM(B16:N16)
A17: Материалы (приоритет 2) | B17: =SUMIFS('Сводный реестр'!$F$2:$F$46,'Сводный реестр'!$A$2:$A$46,"Платёж",'Сводный реестр'!$G$2:$G$46,">="&DATE(2026,10,19),'Сводный реестр'!$G$2:$G$46,"<="&DATE(2026,10,25),'Сводный реестр'!$E$2:$E$46,"Материалы") | C17: =SUMIFS('Сводный реестр'!$F$2:$F$46,'Сводный реестр'!$A$2:$A$46,"Платёж",'Сводный реестр'!$G$2:$G$46,">="&DATE(2026,10,26),'Сводный реестр'!$G$2:$G$46,"<="&DATE(2026,11,1),'Сводный реестр'!$E$2:$E$46,"Материалы") | D17: =SUMIFS('Сводный реестр'!$F$2:$F$46,'Сводный реестр'!$A$2:$A$46,"Платёж",'Сводный реестр'!$G$2:$G$46,">="&DATE(2026,11,2),'Сводный реестр'!$G$2:$G$46,"<="&DATE(2026,11,8),'Сводный реестр'!$E$2:$E$46,"Материалы") | E17: =SUMIFS('Сводный реестр'!$F$2:$F$46,'Сводный реестр'!$A$2:$A$46,"Платёж",'Сводный реестр'!$G$2:$G$46,">="&DATE(2026,11,9),'Сводный реестр'!$G$2:$G$46,"<="&DATE(2026,11,15),'Сводный реестр'!$E$2:$E$46,"Материалы") | F17: =SUMIFS('Сводный реестр'!$F$2:$F$46,'Сводный реестр'!$A$2:$A$46,"Платёж",'Сводный реестр'!$G$2:$G$46,">="&DATE(2026,11,16),'Сводный реестр'!$G$2:$G$46,"<="&DATE(2026,11,22),'Сводный реестр'!$E$2:$E$46,"Материалы") | G17: =SUMIFS('Сводный реестр'!$F$2:$F$46,'Сводный реестр'!$A$2:$A$46,"Платёж",'Сводный реестр'!$G$2:$G$46,">="&DATE(2026,11,23),'Сводный реестр'!$G$2:$G$46,"<="&DATE(2026,11,29),'Сводный реестр'!$E$2:$E$46,"Материалы") | H17: =SUMIFS('Сводный реестр'!$F$2:$F$46,'Сводный реестр'!$A$2:$A$46,"Платёж",'Сводный реестр'!$G$2:$G$46,">="&DATE(2026,11,30),'Сводный реестр'!$G$2:$G$46,"<="&DATE(2026,12,6),'Сводный реестр'!$E$2:$E$46,"Материалы") | I17: =SUMIFS('Сводный реестр'!$F$2:$F$46,'Сводный реестр'!$A$2:$A$46,"Платёж",'Сводный реестр'!$G$2:$G$46,">="&DATE(2026,12,7),'Сводный реестр'!$G$2:$G$46,"<="&DATE(2026,12,13),'Сводный реестр'!$E$2:$E$46,"Материалы") | J17: =SUMIFS('Сводный реестр'!$F$2:$F$46,'Сводный реестр'!$A$2:$A$46,"Платёж",'Сводный реестр'!$G$2:$G$46,">="&DATE(2026,12,14),'Сводный реестр'!$G$2:$G$46,"<="&DATE(2026,12,20),'Сводный реестр'!$E$2:$E$46,"Материалы") | K17: =SUMIFS('Сводный реестр'!$F$2:$F$46,'Сводный реестр'!$A$2:$A$46,"Платёж",'Сводный реестр'!$G$2:$G$46,">="&DATE(2026,12,21),'Сводный реестр'!$G$2:$G$46,"<="&DATE(2026,12,27),'Сводный реестр'!$E$2:$E$46,"Материалы") | L17: =SUMIFS('Сводный реестр'!$F$2:$F$46,'Сводный реестр'!$A$2:$A$46,"Платёж",'Сводный реестр'!$G$2:$G$46,">="&DATE(2026,12,28),'Сводный реестр'!$G$2:$G$46,"<="&DATE(2027,1,3),'Сводный реестр'!$E$2:$E$46,"Материалы") | M17: =SUMIFS('Сводный реестр'!$F$2:$F$46,'Сводный реестр'!$A$2:$A$46,"Платёж",'Сводный реестр'!$G$2:$G$46,">="&DATE(2027,1,4),'Сводный реестр'!$G$2:$G$46,"<="&DATE(2027,1,10),'Сводный реестр'!$E$2:$E$46,"Материалы") | N17: =SUMIFS('Сводный реестр'!$F$2:$F$46,'Сводный реестр'!$A$2:$A$46,"Платёж",'Сводный реестр'!$G$2:$G$46,">="&DATE(2027,1,11),'Сводный реестр'!$G$2:$G$46,"<="&DATE(2027,1,17),'Сводный реестр'!$E$2:$E$46,"Материалы") | O17: =SUM(B17:N17)
A18: Подрядчики (приоритет 2) | B18: =SUMIFS('Сводный реестр'!$F$2:$F$46,'Сводный реестр'!$A$2:$A$46,"Платёж",'Сводный реестр'!$G$2:$G$46,">="&DATE(2026,10,19),'Сводный реестр'!$G$2:$G$46,"<="&DATE(2026,10,25),'Сводный реестр'!$E$2:$E$46,"Подрядчики") | C18: =SUMIFS('Сводный реестр'!$F$2:$F$46,'Сводный реестр'!$A$2:$A$46,"Платёж",'Сводный реестр'!$G$2:$G$46,">="&DATE(2026,10,26),'Сводный реестр'!$G$2:$G$46,"<="&DATE(2026,11,1),'Сводный реестр'!$E$2:$E$46,"Подрядчики") | D18: =SUMIFS('Сводный реестр'!$F$2:$F$46,'Сводный реестр'!$A$2:$A$46,"Платёж",'Сводный реестр'!$G$2:$G$46,">="&DATE(2026,11,2),'Сводный реестр'!$G$2:$G$46,"<="&DATE(2026,11,8),'Сводный реестр'!$E$2:$E$46,"Подрядчики") | E18: =SUMIFS('Сводный реестр'!$F$2:$F$46,'Сводный реестр'!$A$2:$A$46,"Платёж",'Сводный реестр'!$G$2:$G$46,">="&DATE(2026,11,9),'Сводный реестр'!$G$2:$G$46,"<="&DATE(2026,11,15),'Сводный реестр'!$E$2:$E$46,"Подрядчики") | F18: =SUMIFS('Сводный реестр'!$F$2:$F$46,'Сводный реестр'!$A$2:$A$46,"Платёж",'Сводный реестр'!$G$2:$G$46,">="&DATE(2026,11,16),'Сводный реестр'!$G$2:$G$46,"<="&DATE(2026,11,22),'Сводный реестр'!$E$2:$E$46,"Подрядчики") | G18: =SUMIFS('Сводный реестр'!$F$2:$F$46,'Сводный реестр'!$A$2:$A$46,"Платёж",'Сводный реестр'!$G$2:$G$46,">="&DATE(2026,11,23),'Сводный реестр'!$G$2:$G$46,"<="&DATE(2026,11,29),'Сводный реестр'!$E$2:$E$46,"Подрядчики") | H18: =SUMIFS('Сводный реестр'!$F$2:$F$46,'Сводный реестр'!$A$2:$A$46,"Платёж",'Сводный реестр'!$G$2:$G$46,">="&DATE(2026,11,30),'Сводный реестр'!$G$2:$G$46,"<="&DATE(2026,12,6),'Сводный реестр'!$E$2:$E$46,"Подрядчики") | I18: =SUMIFS('Сводный реестр'!$F$2:$F$46,'Сводный реестр'!$A$2:$A$46,"Платёж",'Сводный реестр'!$G$2:$G$46,">="&DATE(2026,12,7),'Сводный реестр'!$G$2:$G$46,"<="&DATE(2026,12,13),'Сводный реестр'!$E$2:$E$46,"Подрядчики") | J18: =SUMIFS('Сводный реестр'!$F$2:$F$46,'Сводный реестр'!$A$2:$A$46,"Платёж",'Сводный реестр'!$G$2:$G$46,">="&DATE(2026,12,14),'Сводный реестр'!$G$2:$G$46,"<="&DATE(2026,12,20),'Сводный реестр'!$E$2:$E$46,"Подрядчики") | K18: =SUMIFS('Сводный реестр'!$F$2:$F$46,'Сводный реестр'!$A$2:$A$46,"Платёж",'Сводный реестр'!$G$2:$G$46,">="&DATE(2026,12,21),'Сводный реестр'!$G$2:$G$46,"<="&DATE(2026,12,27),'Сводный реестр'!$E$2:$E$46,"Подрядчики") | L18: =SUMIFS('Сводный реестр'!$F$2:$F$46,'Сводный реестр'!$A$2:$A$46,"Платёж",'Сводный реестр'!$G$2:$G$46,">="&DATE(2026,12,28),'Сводный реестр'!$G$2:$G$46,"<="&DATE(2027,1,3),'Сводный реестр'!$E$2:$E$46,"Подрядчики") | M18: =SUMIFS('Сводный реестр'!$F$2:$F$46,'Сводный реестр'!$A$2:$A$46,"Платёж",'Сводный реестр'!$G$2:$G$46,">="&DATE(2027,1,4),'Сводный реестр'!$G$2:$G$46,"<="&DATE(2027,1,10),'Сводный реестр'!$E$2:$E$46,"Подрядчики") | N18: =SUMIFS('Сводный реестр'!$F$2:$F$46,'Сводный реестр'!$A$2:$A$46,"Платёж",'Сводный реестр'!$G$2:$G$46,">="&DATE(2027,1,11),'Сводный реестр'!$G$2:$G$46,"<="&DATE(2027,1,17),'Сводный реестр'!$E$2:$E$46,"Подрядчики") | O18: =SUM(B18:N18)
A19: Командировки (приоритет 3) | B19: =SUMIFS('Сводный реестр'!$F$2:$F$46,'Сводный реестр'!$A$2:$A$46,"Платёж",'Сводный реестр'!$G$2:$G$46,">="&DATE(2026,10,19),'Сводный реестр'!$G$2:$G$46,"<="&DATE(2026,10,25),'Сводный реестр'!$E$2:$E$46,"Командировки") | C19: =SUMIFS('Сводный реестр'!$F$2:$F$46,'Сводный реестр'!$A$2:$A$46,"Платёж",'Сводный реестр'!$G$2:$G$46,">="&DATE(2026,10,26),'Сводный реестр'!$G$2:$G$46,"<="&DATE(2026,11,1),'Сводный реестр'!$E$2:$E$46,"Командировки") | D19: =SUMIFS('Сводный реестр'!$F$2:$F$46,'Сводный реестр'!$A$2:$A$46,"Платёж",'Сводный реестр'!$G$2:$G$46,">="&DATE(2026,11,2),'Сводный реестр'!$G$2:$G$46,"<="&DATE(2026,11,8),'Сводный реестр'!$E$2:$E$46,"Командировки") | E19: =SUMIFS('Сводный реестр'!$F$2:$F$46,'Сводный реестр'!$A$2:$A$46,"Платёж",'Сводный реестр'!$G$2:$G$46,">="&DATE(2026,11,9),'Сводный реестр'!$G$2:$G$46,"<="&DATE(2026,11,15),'Сводный реестр'!$E$2:$E$46,"Командировки") | F19: =SUMIFS('Сводный реестр'!$F$2:$F$46,'Сводный реестр'!$A$2:$A$46,"Платёж",'Сводный реестр'!$G$2:$G$46,">="&DATE(2026,11,16),'Сводный реестр'!$G$2:$G$46,"<="&DATE(2026,11,22),'Сводный реестр'!$E$2:$E$46,"Командировки") | G19: =SUMIFS('Сводный реестр'!$F$2:$F$46,'Сводный реестр'!$A$2:$A$46,"Платёж",'Сводный реестр'!$G$2:$G$46,">="&DATE(2026,11,23),'Сводный реестр'!$G$2:$G$46,"<="&DATE(2026,11,29),'Сводный реестр'!$E$2:$E$46,"Командировки") | H19: =SUMIFS('Сводный реестр'!$F$2:$F$46,'Сводный реестр'!$A$2:$A$46,"Платёж",'Сводный реестр'!$G$2:$G$46,">="&DATE(2026,11,30),'Сводный реестр'!$G$2:$G$46,"<="&DATE(2026,12,6),'Сводный реестр'!$E$2:$E$46,"Командировки") | I19: =SUMIFS('Сводный реестр'!$F$2:$F$46,'Сводный реестр'!$A$2:$A$46,"Платёж",'Сводный реестр'!$G$2:$G$46,">="&DATE(2026,12,7),'Сводный реестр'!$G$2:$G$46,"<="&DATE(2026,12,13),'Сводный реестр'!$E$2:$E$46,"Командировки") | J19: =SUMIFS('Сводный реестр'!$F$2:$F$46,'Сводный реестр'!$A$2:$A$46,"Платёж",'Сводный реестр'!$G$2:$G$46,">="&DATE(2026,12,14),'Сводный реестр'!$G$2:$G$46,"<="&DATE(2026,12,20),'Сводный реестр'!$E$2:$E$46,"Командировки") | K19: =SUMIFS('Сводный реестр'!$F$2:$F$46,'Сводный реестр'!$A$2:$A$46,"Платёж",'Сводный реестр'!$G$2:$G$46,">="&DATE(2026,12,21),'Сводный реестр'!$G$2:$G$46,"<="&DATE(2026,12,27),'Сводный реестр'!$E$2:$E$46,"Командировки") | L19: =SUMIFS('Сводный реестр'!$F$2:$F$46,'Сводный реестр'!$A$2:$A$46,"Платёж",'Сводный реестр'!$G$2:$G$46,">="&DATE(2026,12,28),'Сводный реестр'!$G$2:$G$46,"<="&DATE(2027,1,3),'Сводный реестр'!$E$2:$E$46,"Командировки") | M19: =SUMIFS('Сводный реестр'!$F$2:$F$46,'Сводный реестр'!$A$2:$A$46,"Платёж",'Сводный реестр'!$G$2:$G$46,">="&DATE(2027,1,4),'Сводный реестр'!$G$2:$G$46,"<="&DATE(2027,1,10),'Сводный реестр'!$E$2:$E$46,"Командировки") | N19: =SUMIFS('Сводный реестр'!$F$2:$F$46,'Сводный реестр'!$A$2:$A$46,"Платёж",'Сводный реестр'!$G$2:$G$46,">="&DATE(2027,1,11),'Сводный реестр'!$G$2:$G$46,"<="&DATE(2027,1,17),'Сводный реестр'!$E$2:$E$46,"Командировки") | O19: =SUM(B19:N19)
A20: Прочие расходы (приоритет 3) | B20: =SUMIFS('Сводный реестр'!$F$2:$F$46,'Сводный реестр'!$A$2:$A$46,"Платёж",'Сводный реестр'!$G$2:$G$46,">="&DATE(2026,10,19),'Сводный реестр'!$G$2:$G$46,"<="&DATE(2026,10,25),'Сводный реестр'!$E$2:$E$46,"Прочие расходы") | C20: =SUMIFS('Сводный реестр'!$F$2:$F$46,'Сводный реестр'!$A$2:$A$46,"Платёж",'Сводный реестр'!$G$2:$G$46,">="&DATE(2026,10,26),'Сводный реестр'!$G$2:$G$46,"<="&DATE(2026,11,1),'Сводный реестр'!$E$2:$E$46,"Прочие расходы") | D20: =SUMIFS('Сводный реестр'!$F$2:$F$46,'Сводный реестр'!$A$2:$A$46,"Платёж",'Сводный реестр'!$G$2:$G$46,">="&DATE(2026,11,2),'Сводный реестр'!$G$2:$G$46,"<="&DATE(2026,11,8),'Сводный реестр'!$E$2:$E$46,"Прочие расходы") | E20: =SUMIFS('Сводный реестр'!$F$2:$F$46,'Сводный реестр'!$A$2:$A$46,"Платёж",'Сводный реестр'!$G$2:$G$46,">="&DATE(2026,11,9),'Сводный реестр'!$G$2:$G$46,"<="&DATE(2026,11,15),'Сводный реестр'!$E$2:$E$46,"Прочие расходы") | F20: =SUMIFS('Сводный реестр'!$F$2:$F$46,'Сводный реестр'!$A$2:$A$46,"Платёж",'Сводный реестр'!$G$2:$G$46,">="&DATE(2026,11,16),'Сводный реестр'!$G$2:$G$46,"<="&DATE(2026,11,22),'Сводный реестр'!$E$2:$E$46,"Прочие расходы") | G20: =SUMIFS('Сводный реестр'!$F$2:$F$46,'Сводный реестр'!$A$2:$A$46,"Платёж",'Сводный реестр'!$G$2:$G$46,">="&DATE(2026,11,23),'Сводный реестр'!$G$2:$G$46,"<="&DATE(2026,11,29),'Сводный реестр'!$E$2:$E$46,"Прочие расходы") | H20: =SUMIFS('Сводный реестр'!$F$2:$F$46,'Сводный реестр'!$A$2:$A$46,"Платёж",'Сводный реестр'!$G$2:$G$46,">="&DATE(2026,11,30),'Сводный реестр'!$G$2:$G$46,"<="&DATE(2026,12,6),'Сводный реестр'!$E$2:$E$46,"Прочие расходы") | I20: =SUMIFS('Сводный реестр'!$F$2:$F$46,'Сводный реестр'!$A$2:$A$46,"Платёж",'Сводный реестр'!$G$2:$G$46,">="&DATE(2026,12,7),'Сводный реестр'!$G$2:$G$46,"<="&DATE(2026,12,13),'Сводный реестр'!$E$2:$E$46,"Прочие расходы") | J20: =SUMIFS('Сводный реестр'!$F$2:$F$46,'Сводный реестр'!$A$2:$A$46,"Платёж",'Сводный реестр'!$G$2:$G$46,">="&DATE(2026,12,14),'Сводный реестр'!$G$2:$G$46,"<="&DATE(2026,12,20),'Сводный реестр'!$E$2:$E$46,"Прочие расходы") | K20: =SUMIFS('Сводный реестр'!$F$2:$F$46,'Сводный реестр'!$A$2:$A$46,"Платёж",'Сводный реестр'!$G$2:$G$46,">="&DATE(2026,12,21),'Сводный реестр'!$G$2:$G$46,"<="&DATE(2026,12,27),'Сводный реестр'!$E$2:$E$46,"Прочие расходы") | L20: =SUMIFS('Сводный реестр'!$F$2:$F$46,'Сводный реестр'!$A$2:$A$46,"Платёж",'Сводный реестр'!$G$2:$G$46,">="&DATE(2026,12,28),'Сводный реестр'!$G$2:$G$46,"<="&DATE(2027,1,3),'Сводный реестр'!$E$2:$E$46,"Прочие расходы") | M20: =SUMIFS('Сводный реестр'!$F$2:$F$46,'Сводный реестр'!$A$2:$A$46,"Платёж",'Сводный реестр'!$G$2:$G$46,">="&DATE(2027,1,4),'Сводный реестр'!$G$2:$G$46,"<="&DATE(2027,1,10),'Сводный реестр'!$E$2:$E$46,"Прочие расходы") | N20: =SUMIFS('Сводный реестр'!$F$2:$F$46,'Сводный реестр'!$A$2:$A$46,"Платёж",'Сводный реестр'!$G$2:$G$46,">="&DATE(2027,1,11),'Сводный реестр'!$G$2:$G$46,"<="&DATE(2027,1,17),'Сводный реестр'!$E$2:$E$46,"Прочие расходы") | O20: =SUM(B20:N20)
A21: Итого платежи | B21: =B10+B11+B12+B13+B14+B15+B16+B17+B18+B19+B20 | C21: =C10+C11+C12+C13+C14+C15+C16+C17+C18+C19+C20 | D21: =D10+D11+D12+D13+D14+D15+D16+D17+D18+D19+D20 | E21: =E10+E11+E12+E13+E14+E15+E16+E17+E18+E19+E20 | F21: =F10+F11+F12+F13+F14+F15+F16+F17+F18+F19+F20 | G21: =G10+G11+G12+G13+G14+G15+G16+G17+G18+G19+G20 | H21: =H10+H11+H12+H13+H14+H15+H16+H17+H18+H19+H20 | I21: =I10+I11+I12+I13+I14+I15+I16+I17+I18+I19+I20 | ... O21: =O10+O11+O12+O13+O14+O15+O16+O17+O18+O19+O20
A23: Чистый денежный поток | B23: =B7-B21 | C23: =C7-C21 | D23: =D7-D21 | E23: =E7-E21 | F23: =F7-F21 | G23: =G7-G21 | H23: =H7-H21 | I23: =I7-I21 | ... O23: =O7-O21
A24: Остаток на начало недели | B24: ='Параметры и проверки'!$C$5 | C24: =B25 | D24: =C25 | E24: =D25 | F24: =E25 | G24: =F25 | H24: =G25 | I24: =H25 | J24: =I25 | ... N24: =M25
A25: Остаток на конец недели | B25: =B24+B23 | C25: =C24+C23 | D25: =D24+D23 | E25: =E24+E23 | F25: =F24+F23 | G25: =G24+G23 | H25: =H24+H23 | I25: =I24+I23 | ... N25: =N24+N23
A26: Доступно с учётом кредитных лимитов | B26: =B25+'Параметры и проверки'!$C$6 | C26: =C25+'Параметры и проверки'!$C$6 | D26: =D25+'Параметры и проверки'!$C$6 | E26: =E25+'Параметры и проверки'!$C$6 | F26: =F25+'Параметры и проверки'!$C$6 | G26: =G25+'Параметры и проверки'!$C$6 | H26: =H25+'Параметры и проверки'!$C$6 | I26: =I25+'Параметры и проверки'!$C$6 | ... N26: =N25+'Параметры и проверки'!$C$6
A27: Состояние недели | B27: =IF(B25<0,"РАЗРЫВ",IF(B25<'Параметры и проверки'!$C$7,"Ниже порога","Норма")) | C27: =IF(C25<0,"РАЗРЫВ",IF(C25<'Параметры и проверки'!$C$7,"Ниже порога","Норма")) | D27: =IF(D25<0,"РАЗРЫВ",IF(D25<'Параметры и проверки'!$C$7,"Ниже порога","Норма")) | E27: =IF(E25<0,"РАЗРЫВ",IF(E25<'Параметры и проверки'!$C$7,"Ниже порога","Норма")) | F27: =IF(F25<0,"РАЗРЫВ",IF(F25<'Параметры и проверки'!$C$7,"Ниже порога","Норма")) | G27: =IF(G25<0,"РАЗРЫВ",IF(G25<'Параметры и проверки'!$C$7,"Ниже порога","Норма")) | H27: =IF(H25<0,"РАЗРЫВ",IF(H25<'Параметры и проверки'!$C$7,"Ниже порога","Норма")) | I27: =IF(I25<0,"РАЗРЫВ",IF(I25<'Параметры и проверки'!$C$7,"Ниже порога","Норма")) | ... N27: =IF(N25<0,"РАЗРЫВ",IF(N25<'Параметры и проверки'!$C$7,"Ниже порога","Норма"))

Sheet Параметры и проверки
B2: Параметры расчёта
B4: Дата начала прогноза | C4: 46314
B5: Остаток денежных средств на старте | C5: 2850000
B6: Свободные кредитные лимиты | C6: 6000000
B7: Порог тревоги | C7: 500000
B8: Горизонт, недель | C8: 13
B9: Компания | C9: Демо-компания (условные данные)
B10: Дата расчёта | C10: 46311
B12: Контрольные суммы
B13: Обязательств в расчёте, шт. | C13: 45
B14: Поступления за горизонт | C14: 27850000
B15: Платежи за горизонт | C15: 27887500
B16: Чистый поток | C16: -37500
B17: Остаток на конец горизонта | C17: 2812500
B18: Минимальный остаток | C18: -2892500
B20: Замечания к данным
B21: Замечаний нет: все строки прошли проверку.

Sheet Сводный реестр
A1: Тип | B1: Проект | C1: Контрагент | D1: Основание | E1: Статья ДДС | F1: Сумма | G1: Дата | H1: Статус | I1: Приоритет | J1: Вид деятельности | K1: Источник | L1: Неделя | M1: Период недели | N1: Комментарий
A2: Поступление | B2: Объект 1 — ТЦ, остекление | C2: Заказчик А | D2: Договор 14/2026, окончательный расчёт | E2: Поступления от заказчиков | F2: 1800000 | G2: 46318 | H2: Подтверждено | J2: Операционная | K2: Реестр | L2: 1 | M2: 19.10 - 25.10 | N2: Акт подписан
A3: Поступление | B3: Объект 2 — БЦ, фасад | C3: Заказчик Б | D3: Договор 21/2026, аванс 30% | E3: Поступления от заказчиков | F3: 4200000 | G3: 46332 | H3: Подтверждено | J3: Операционная | K3: Реестр | L3: 3 | M3: 02.11 - 08.11 | N3: Аванс по подписанному договору
A4: Поступление | B4: Объект 3 — склад, окна | C4: Заказчик В | D4: Договор 19/2026, этап 1 | E4: Поступления от заказчиков | F4: 3200000 | G4: 46346 | H4: План | J4: Операционная | K4: Реестр | L4: 5 | M4: 16.11 - 22.11 | N4: Срок зависит от подписания КС-2
A5: Поступление | B5: Объект 3 — склад, окна | C5: Заказчик Д | D5: Договор 24/2026, аванс 40% | E5: Поступления от заказчиков | F5: 3600000 | G5: 46358 | H5: План | J5: Операционная | K5: Реестр | L5: 7 | M5: 30.11 - 06.12 | N5: Договор подписан, ждём оплату
A6: Поступление | B6: Объект 2 — БЦ, фасад | C6: Заказчик Б | D6: Договор 21/2026, этап 2 | E6: Поступления от заказчиков | F6: 5200000 | G6: 46367 | H6: План | J6: Операционная | K6: Реестр | L6: 8 | M6: 07.12 - 13.12
A7: Поступление | B7: Объект 3 — склад, окна | C7: Заказчик В | D7: Договор 19/2026, этап 2 | E7: Поступления от заказчиков | F7: 4100000 | G7: 46372 | H7: План | J7: Операционная | K7: Реестр | L7: 9 | M7: 14.12 - 20.12
A8: Поступление | B8: Объект 1 — ТЦ, остекление | C8: Заказчик Г | D8: Договор 23/2026, аванс | E8: Поступления от заказчиков | F8: 2800000 | G8: 46381 | H8: План | J8: Операционная | K8: Реестр | L8: 10 | M8: 21.12 - 27.12 | N8: Договор на согласовании
A9: Поступление | B9: Объект 1 — ТЦ, остекление | C9: Заказчик Г | D9: Договор 23/2026, этап 1 | E9: Поступления от заказчиков | F9: 2300000 | G9: 46392 | H9: План | J9: Операционная | K9: Реестр | L9: 12 | M9: 04.01 - 10.01
A10: Поступление | B10: Объект 1 — ТЦ, остекление | C10: Заказчик А | D10: Доп. соглашение 2 | E10: Поступления от заказчиков | F10: 650000 | G10: 46403 | H10: План | J10: Операционная | K10: Реестр | L10: 13 | M10: 11.01 - 17.01 | N10: Дополнительные работы
A11: Платёж | B11: Общие | C11: Персонал | D11: Зарплата за октябрь | E11: ФОТ | F11: 1500000 | G11: 46331 | H11: Подтверждено | I11: 1 | J11: Операционная | K11: Реестр | L11: 3 | M11: 02.11 - 08.11
A12: Платёж | B12: Общие | C12: Персонал | D12: Зарплата за ноябрь | E12: ФОТ | F12: 1500000 | G12: 46360 | H12: План | I12: 1 | J12: Операционная | K12: Реестр | L12: 7 | M12: 30.11 - 06.12
A13: Платёж | B13: Общие | C13: Персонал | D13: Зарплата за декабрь | E13: ФОТ | F13: 1620000 | G13: 46399 | H13: План | I13: 1 | J13: Операционная | K13: Реестр | L13: 13 | M13: 11.01 - 17.01 | N13: Выше обычного: годовая премия
A14: Платёж | B14: Общие | C14: ФНС | D14: НДС за III квартал, 1/3 | E14: Налоги | F14: 1150000 | G14: 46323 | H14: Подтверждено | I14: 1 | J14: Операционная | K14: Реестр | L14: 2 | M14: 26.10 - 01.11
A15: Платёж | B15: Общие | C15: ФНС | D15: Налог на прибыль за 9 месяцев | E15: Налоги | F15: 480000 | G15: 46323 | H15: Подтверждено | I15: 1 | J15: Операционная | K15: Реестр | L15: 2 | M15: 26.10 - 01.11
A16: Платёж | B16: Общие | C16: ФНС | D16: НДС за III квартал, 2/3 | E16: Налоги | F16: 1150000 | G16: 46354 | H16: План | I16: 1 | J16: Операционная | K16: Реестр | L16: 6 | M16: 23.11 - 29.11
A17: Платёж | B17: Общие | C17: ФНС | D17: НДС за III квартал, 3/3 | E17: Налоги | F17: 1150000 | G17: 46384 | H17: План | I17: 1 | J17: Операционная | K17: Реестр | L17: 11 | M17: 28.12 - 03.01
A18: Платёж | B18: Общие | C18: ФНС | D18: Страховые взносы за октябрь | E18: Страховые взносы | F18: 870000 | G18: 46323 | H18: Подтверждено | I18: 1 | J18: Операционная | K18: Реестр | L18: 2 | M18: 26.10 - 01.11
A19: Платёж | B19: Общие | C19: ФНС | D19: Страховые взносы за ноябрь | E19: Страховые взносы | F19: 870000 | G19: 46354 | H19: План | I19: 1 | J19: Операционная | K19: Реестр | L19: 6 | M19: 23.11 - 29.11
A20: Платёж | B20: Общие | C20: ФНС | D20: Страховые взносы за декабрь | E20: Страховые взносы | F20: 890000 | G20: 46384 | H20: План | I20: 1 | J20: Операционная | K20: Реестр | L20: 11 | M20: 28.12 - 03.01
A21: Платёж | B21: Объект 2 — БЦ, фасад | C21: Подрядчик 1 | D21: Монтажные работы, этап 1 | E21: Подрядчики | F21: 1850000 | G21: 46338 | H21: Подтверждено | I21: 2 | J21: Операционная | K21: Реестр | L21: 4 | M21: 09.11 - 15.11 | N21: Счёт выставлен
A22: Платёж | B22: Объект 2 — БЦ, фасад | C22: Подрядчик 1 | D22: Монтажные работы, этап 2 | E22: Подрядчики | F22: 1600000 | G22: 46352 | H22: План | I22: 2 | J22: Операционная | K22: Реестр | L22: 6 | M22: 23.11 - 29.11
A23: Платёж | B23: Объект 3 — склад, окна | C23: Подрядчик 2 | D23: Демонтаж и подготовка | E23: Подрядчики | F23: 740000 | G23: 46359 | H23: План | I23: 2 | J23: Операционная | K23: Реестр | L23: 7 | M23: 30.11 - 06.12
A24: Платёж | B24: Объект 2 — БЦ, фасад | C24: Подрядчик 1 | D24: Монтажные работы, этап 3 | E24: Подрядчики | F24: 1900000 | G24: 46378 | H24: План | I24: 2 | J24: Операционная | K24: Реестр | L24: 10 | M24: 21.12 - 27.12
A25: Платёж | B25: Объект 1 — ТЦ, остекление | C25: Поставщик 1 | D25: Стеклопакеты, партия 1 | E25: Материалы | F25: 900000 | G25: 46324 | H25: Подтверждено | I25: 2 | J25: Операционная | K25: Реестр | L25: 2 | M25: 26.10 - 01.11
A26: Платёж | B26: Объект 2 — БЦ, фасад | C26: Поставщик 2 | D26: Алюминиевый профиль | E26: Материалы | F26: 900000 | G26: 46345 | H26: План | I26: 2 | J26: Операционная | K26: Реестр | L26: 5 | M26: 16.11 - 22.11
A27: Платёж | B27: Объект 2 — БЦ, фасад | C27: Поставщик 1 | D27: Стеклопакеты, партия 2 | E27: Материалы | F27: 1340000 | G27: 46365 | H27: План | I27: 2 | J27: Операционная | K27: Реестр | L27: 8 | M27: 07.12 - 13.12
A28: Платёж | B28: Объект 3 — склад, окна | C28: Поставщик 3 | D28: Фурнитура и крепёж | E28: Материалы | F28: 380000 | G28: 46379 | H28: План | I28: 2 | J28: Операционная | K28: Реестр | L28: 10 | M28: 21.12 - 27.12
A29: Платёж | B29: Общие | C29: Банк 2 | D29: Погашение части кредитной линии | E29: Погашение кредита | F29: 500000 | G29: 46402 | H29: План | I29: 1 | J29: Финансовая | K29: Реестр | L29: 13 | M29: 11.01 - 17.01 | N29: По графику продления
A30: Платёж | B30: Объект 3 — склад, окна | C30: Прочие | D30: Командировка на объект | E30: Командировки | F30: 140000 | G30: 46339 | H30: План | I30: 3 | J30: Операционная | K30: Реестр | L30: 4 | M30: 09.11 - 15.11 | N30: Можно перенести
A31: Платёж | B31: Общие | C31: Прочие | D31: Обучение сотрудников | E31: Прочие расходы | F31: 210000 | G31: 46360 | H31: План | I31: 3 | J31: Операционная | K31: Реестр | L31: 7 | M31: 30.11 - 06.12 | N31: Можно перенести
A32: Платёж | B32: Общие | C32: Персонал | D32: Аванс за октябрь | E32: ФОТ | F32: 1450000 | G32: 46315 | H32: План | I32: 1 | J32: Операционная | K32: Регулярные | L32: 1 | M32: 19.10 - 25.10 | N32: Зарплата идёт отдельно: сумма меняется
A33: Платёж | B33: Общие | C33: Банк 2 | D33: Проценты по кредитной линии, октябрь | E33: Проценты по кредитам | F33: 32500 | G33: 46325 | H33: План | I33: 1 | J33: Финансовая | K33: Регулярные | L33: 2 | M33: 26.10 - 01.11 | N33: 2 000 000 × 19,5% / 12
A34: Платёж | B34: Общие | C34: Прочие | D34: Связь, ПО, канцелярия | E34: Прочие расходы | F34: 95000 | G34: 46325 | H34: План | I34: 3 | J34: Операционная | K34: Регулярные | L34: 2 | M34: 26.10 - 01.11
A35: Платёж | B35: Общие | C35: Арендодатель | D35: Аренда офиса и склада, ноябрь | E35: Аренда | F35: 320000 | G35: 46331 | H35: План | I35: 2 | J35: Операционная | K35: Регулярные | L35: 3 | M35: 02.11 - 08.11
A36: Платёж | B36: Общие | C36: Лизинговая компания | D36: Лизинг автовышки | E36: Лизинг | F36: 185000 | G36: 46339 | H36: План | I36: 2 | J36: Финансовая | K36: Регулярные | L36: 4 | M36: 09.11 - 15.11 | N36: График лизинга, 36 платежей; перенос с 15.11.2026 (раньше)
A37: Платёж | B37: Общие | C37: Персонал | D37: Аванс за ноябрь | E37: ФОТ | F37: 1450000 | G37: 46346 | H37: План | I37: 1 | J37: Операционная | K37: Регулярные | L37: 5 | M37: 16.11 - 22.11 | N37: Зарплата идёт отдельно: сумма меняется
A38: Платёж | B38: Общие | C38: Банк 2 | D38: Проценты по кредитной линии, ноябрь | E38: Проценты по кредитам | F38: 32500 | G38: 46356 | H38: План | I38: 1 | J38: Финансовая | K38: Регулярные | L38: 7 | M38: 30.11 - 06.12 | N38: 2 000 000 × 19,5% / 12
A39: Платёж | B39: Общие | C39: Прочие | D39: Связь, ПО, канцелярия | E39: Прочие расходы | F39: 95000 | G39: 46356 | H39: План | I39: 3 | J39: Операционная | K39: Регулярные | L39: 7 | M39: 30.11 - 06.12
A40: Платёж | B40: Общие | C40: Арендодатель | D40: Аренда офиса и склада, декабрь | E40: Аренда | F40: 320000 | G40: 46360 | H40: План | I40: 2 | J40: Операционная | K40: Регулярные | L40: 7 | M40: 30.11 - 06.12 | N40: перенос с 05.12.2026 (раньше)
...

Sheet Разрывы
A1: Кассовые разрывы и варианты закрытия
A3: Неделя | B3: Дата | C3: Состояние | D3: Нехватка | E3: Можно перенести | F3: Что переносить | G3: Покрытие лимитом
A4: 2 | B4: 46321 | C4: разрыв | D4: 327500 | E4: 95000 | F4: Прочие — 95 000 | G4: да, лимита хватает
A5: 4 | B5: 46335 | C5: разрыв | D5: 122500 | E5: 140000 | F5: Прочие — 140 000 | G5: да, лимита хватает
A6: 6 | B6: 46349 | C6: разрыв | D6: 2892500 | E6: 0 | F6: платежей приоритета 3 на этой неделе нет | G6: да, лимита хватает
A7: 7 | B7: 46356 | C7: разрыв | D7: 2190000 | E7: 305000 | F7: Прочие — 210 000; Прочие — 95 000 | G7: да, лимита хватает
A9: Перенос предлагается, но не применяется автоматически: решение принимает финансист.
